Workbook

Sheet 판정
A1: 번호 | B1: 시각 | C1: 내 말 | D1: 유형 | E1: 대상 애니 대사 | F1: 판정 | G1: 판정 이유 | H1: 그 순간 애니 대사(참고) | I1: 사용자 확인 | J1: 고친 판정 | K1: 메모
A2: 0 | B2: 0:07.8 | C2: 마파 | D2: 반응·혼잣말
A3: 1 | B3: 0:18.0 | C3: (숨을 들이마시고 헛기침하는 소리) | D3: 소리·감탄
A4: 2 | B4: 0:27.0 | C4: 시작 | D4: 반응·혼잣말
A5: 3 | B5: 0:49.3 | C5: いつも | D5: 따라함 | E5: （デンジ）いつも見る夢だ | F5: 맞음 | H5: （デンジ）いつも見る夢だ / いつも見て いつも忘れる夢…
A6: 4 | B6: 0:51.5 | C6: 見る夢だ | D6: 따라함 | E6: （デンジ）いつも見る夢だ | F6: 맞음 | H6: （デンジ）いつも見る夢だ / いつも見て いつも忘れる夢…
A7: 5 | B7: 0:52.8 | C7: 항상보는 | D7: 옮김 | E7: （デンジ）いつも見る夢だ | F7: 맞음 | G7: いつも見る → 항상 보는 | H7: （デンジ）いつも見る夢だ / いつも見て いつも忘れる夢…
A8: 6 | B8: 0:55.4 | C8: 꿈이다 | D8: 옮김 | E8: （デンジ）いつも見る夢だ | F8: 맞음 | G8: 夢だ → 꿈이다 | H8: （デンジ）いつも見る夢だ / いつも見て いつも忘れる夢…
A9: 7 | B9: 0:57.0 | C9: 항상 보고 | D9: 옮김 | E9: いつも見て いつも忘れる夢… | F9: 맞음 | G9: いつも見て → 항상 보고 | H9: （デンジ）いつも見る夢だ / いつも見て いつも忘れる夢…
A10: 8 | B10: 0:58.9 | C10: 항상 잊는 꿈 | D10: 옮김 | E10: いつも見て いつも忘れる夢… | F10: 맞음 | G10: いつも忘れる夢 → 항상 잊는 꿈 | H10: （デンジ）いつも見る夢だ / いつも見て いつも忘れる夢…
A11: 9 | B11: 1:16.0 | C11: ポチタ出てこいよ | D11: 따라함 | E11: ポチタ 出てこいよ | F11: 맞음 | H11: （ポチタ）デンジ / （幼少期デンジ）あ… ポチタ！ / ポチタ 出てこいよ
A12: 10 | B12: 1:17.8 | C12: 포치타 나와 | D12: 옮김 | E12: ポチタ 出てこいよ | F12: 맞음 | H12: （ポチタ）デンジ / （幼少期デンジ）あ… ポチタ！ / ポチタ 出てこいよ
A13: 11 | B13: 1:20.0 | C13: (숨 들이마시는 소리) | D13: 소리·감탄 | H13: （幼少期デンジ）あ… ポチタ！ / ポチタ 出てこいよ / ポチタ 出てこいよ
A14: 12 | B14: 1:23.0 | C14: 음 무슨 말인지 몰라 | D14: 못알아들음 | E14: 夢の中くらい 撫(な)でさせてくれ | F14: 못 알아들음 | H14: ポチタ 出てこいよ / 夢の中くらい 撫(な)でさせてくれ / （ポチタ）デンジ
A15: 13 | B15: 1:34.0 | C15: 絶対に開けちゃダメだ | D15: 따라함 | E15: （ポチタ） 絶対に開けちゃダメだ | F15: 맞음 | H15: （ポチタ）デンジ / [추정] （ポチタ） 絶対に開けちゃダメだ / [추정] ハッ…
A16: 14 | B16: 1:36.8 | C16: 절대로 열면 안 돼 | D16: 옮김 | E16: [추정] （ポチタ） 絶対に開けちゃダメだ | F16: 맞음 | H16: （ポチタ）デンジ / [추정] （ポチタ） 絶対に開けちゃダメだ / [추정] ハッ…
A17: 15 | B17: 2:04.7 | C17: なんだうるさいな | D17: 따라함 | E17: なんじゃ うるさいのお…！ | F17: 대체로 맞음 | G17: 파워 말투 なんじゃ…のお를 표준어 なんだ…な로 | H17: なんじゃ うるさいのお…！ / はあ… / なんか悪夢を…
A18: 16 | B18: 2:06.0 | C18: 뭐야 시끄럽게 | D18: 옮김 | E18: なんじゃ うるさいのお…！ | F18: 맞음 | H18: なんじゃ うるさいのお…！ / はあ… / なんか悪夢を…
A19: 17 | B19: 2:11.0 | C19: 뭔가 악몽을 | D19: 옮김 | E19: なんか悪夢を… | F19: 맞음 | H19: はあ… / なんか悪夢を… / なんか悪夢を…
A20: 18 | B20: 2:26.0 | C20: 이거 아직 꿈? | D20: 옮김 | E20: まだこれ夢？ | F20: 맞음 | H20: なんか悪夢を… / [시각추정] （デンジ）ん～… / [추정] まだこれ夢？
A21: 19 | B21: 2:32.0 | C21: 아 이거 많이 들었는데 까먹었네 | D21: 못알아들음 | E21: （パワー）なに寝ぼけとるんじゃ！ | F21: 못 알아들음 | G21: 많이 들었는데 까먹었다고 함 | H21: がっ…！ / かはっ！ / うっ…！
A22: 20 | B22: 2:34.9 | C22: 잠꼬대하냐 이런 건데 | D22: 추측 | E22: （パワー）なに寝ぼけとるんじゃ！ | F22: 대체로 맞음 | G22: 寝ぼける(잠이 덜 깨다)를 잠꼬대로 짐작 | H22: かはっ！ / うっ…！ / ん…
A23: 21 | B23: 2:47.0 | C23: 꿈이 아니잖아 | D23: 옮김 | E23: 夢じゃ… ねえ… | F23: 맞음 | H23: なアんじゃ このパワーは!? / （デンジ）うっ / 夢じゃ… ねえ…
A24: 22 | B24: 2:51.0 | C24: 음 | D24: 소리·감탄 | H24: なアんじゃ このパワーは!? / （デンジ）うっ / 夢じゃ… ねえ…
A25: 23 | B25: 3:20.0 | C25: 응? 마키마? | D25: 반응·혼잣말 | H25: [시각추정] ♪ ダーリンベイビーダーリン / [시각추정] ♪ 半端なくラブ！ときらめき / [시각추정] ♪ 浮き足立つフィロソフィ
A26: 24 | B26: 3:55.0 | C26: 포치타 귀엽네. | D26: 반응·혼잣말 | H26: [시각추정] ♪ ザラメが溶けてゲロになりそう / [시각추정] ♪ 瞳孔バチ開いて溺れ死にそう / [시각추정] ♪ 今この世で君だけ大正解
A27: 25 | B27: 5:17.0 | C27: 잠깐만. | D27: 반응·혼잣말 | H27: [시각추정] ♪ ザラメが溶けてゲロになりそう / [시각추정] ♪ 瞳孔バチ開いて溺れ死にそう / [시각추정] ♪ 今この世で君だけ大正解
A28: 26 | B28: 5:19.0 | C28: 가타카나 한번 읽어봅시다. | D28: 반응·혼잣말 | H28: [시각추정] ♪ ザラメが溶けてゲロになりそう / [시각추정] ♪ 瞳孔バチ開いて溺れ死にそう / [시각추정] ♪ 今この世で君だけ大正解
A29: 27 | B29: 5:22.4 | C29: 체인소 맨인 건 알지만. | D29: 반응·혼잣말 | H29: [시각추정] ♪ ザラメが溶けてゲロになりそう / [시각추정] ♪ 瞳孔バチ開いて溺れ死にそう / [시각추정] ♪ 今この世で君だけ大正解
A30: 28 | B30: 5:28.2 | C30: チ | D30: 읽기 | E30: 제목 チェンソーマン | F30: 맞음 | G30: 한 글자씩 | H30: [시각추정] ♪ 今この世で君だけ大正解
A31: 29 | B31: 5:31.0 | C31: ェ | D31: 읽기 | E31: 제목 チェンソーマン | F31: 맞음 | H31: [시각추정] ♪ 今この世で君だけ大正解
A32: 30 | B32: 5:33.0 | C32: ン | D32: 읽기 | E32: 제목 チェンソーマン | F32: 맞음
A33: 31 | B33: 5:35.0 | C33: ソ ー マ ン | D33: 읽기 | E33: 제목 チェンソーマン | F33: 맞음
A34: 32 | B34: 5:40.8 | C34: チェン | D34: 읽기 | E34: 제목 チェンソーマン | F34: 맞음
A35: 33 | B35: 5:42.8 | C35: ソーマン | D35: 읽기 | E35: 제목 チェンソーマン | F35: 맞음
A36: 34 | B36: 5:48.1 | C36: 이는 어디 간 거야? | D36: 반응·혼잣말
A37: 35 | B37: 5:49.9 | C37: チェンソーマン? | D37: 읽기 | E37: 제목 チェンソーマン | F37: 맞음 | G37: 장음 ー에서 막힘
A38: 36 | B38: 5:53.0 | C38: 뭐야 이거. | D38: 반응·혼잣말
A39: 37 | B39: 5:55.3 | C39: 왜 체인소맨... | D39: 반응·혼잣말
A40: 38 | B40: 5:59.0 | C40: 체인소맨을 가타카나로 チェンソーマン이라고 하는구만.. | D40: 반응·혼잣말
...

Sheet 요약
A1: 1편 청해 판정 요약 (녹화 0:00~105:25, 내 말 669줄)
A3: 유형 | B3: 줄 수
A4: 따라함 | B4: =COUNTIF(판정!D:D,"따라함")
A5: 옮김 | B5: =COUNTIF(판정!D:D,"옮김")
A6: 추측 | B6: =COUNTIF(판정!D:D,"추측")
A7: 못알아들음 | B7: =COUNTIF(판정!D:D,"못알아들음")
A8: 읽기 | B8: =COUNTIF(판정!D:D,"읽기")
A9: 기타 | B9: =COUNTIF(판정!D:D,"기타")
A10: 반응·혼잣말 | B10: =COUNTIF(판정!D:D,"반응·혼잣말")
A11: 소리·감탄 | B11: =COUNTIF(판정!D:D,"소리·감탄")
A12: 합계 | B12: =SUM(B4:B11)
A14: 판정 (대사에 반응한 줄) | B14: 따라함 | C14: 옮김 | D14: 추측 | E14: 모르겠다고 함 | F14: 합계 | G14: 비율
A15: 맞음 | B15: =COUNTIFS(판정!D:D,"따라함",판정!F:F,"맞음") | C15: =COUNTIFS(판정!D:D,"옮김",판정!F:F,"맞음") | D15: =COUNTIFS(판정!D:D,"추측",판정!F:F,"맞음") | E15: =COUNTIFS(판정!D:D,"못알아들음",판정!F:F,"맞음") | F15: =SUM(B14:E14) | G15: =IF(F20=0,0,F14/F20)
A16: 대체로 맞음 | B16: =COUNTIFS(판정!D:D,"따라함",판정!F:F,"대체로 맞음") | C16: =COUNTIFS(판정!D:D,"옮김",판정!F:F,"대체로 맞음") | D16: =COUNTIFS(판정!D:D,"추측",판정!F:F,"대체로 맞음") | E16: =COUNTIFS(판정!D:D,"못알아들음",판정!F:F,"대체로 맞음") | F16: =SUM(B15:E15) | G16: =IF(F20=0,0,F15/F20)
A17: 조금 맞음 | B17: =COUNTIFS(판정!D:D,"따라함",판정!F:F,"조금 맞음") | C17: =COUNTIFS(판정!D:D,"옮김",판정!F:F,"조금 맞음") | D17: =COUNTIFS(판정!D:D,"추측",판정!F:F,"조금 맞음") | E17: =COUNTIFS(판정!D:D,"못알아들음",판정!F:F,"조금 맞음") | F17: =SUM(B16:E16) | G17: =IF(F20=0,0,F16/F20)
A18: 틀림 | B18: =COUNTIFS(판정!D:D,"따라함",판정!F:F,"틀림") | C18: =COUNTIFS(판정!D:D,"옮김",판정!F:F,"틀림") | D18: =COUNTIFS(판정!D:D,"추측",판정!F:F,"틀림") | E18: =COUNTIFS(판정!D:D,"못알아들음",판정!F:F,"틀림") | F18: =SUM(B17:E17) | G18: =IF(F20=0,0,F17/F20)
A19: 못 알아들음 | B19: =COUNTIFS(판정!D:D,"따라함",판정!F:F,"못 알아들음") | C19: =COUNTIFS(판정!D:D,"옮김",판정!F:F,"못 알아들음") | D19: =COUNTIFS(판정!D:D,"추측",판정!F:F,"못 알아들음") | E19: =COUNTIFS(판정!D:D,"못알아들음",판정!F:F,"못 알아들음") | F19: =SUM(B18:E18) | G19: =IF(F20=0,0,F18/F20)
A20: 확인 불가 | B20: =COUNTIFS(판정!D:D,"따라함",판정!F:F,"확인 불가") | C20: =COUNTIFS(판정!D:D,"옮김",판정!F:F,"확인 불가") | D20: =COUNTIFS(판정!D:D,"추측",판정!F:F,"확인 불가") | E20: =COUNTIFS(판정!D:D,"못알아들음",판정!F:F,"확인 불가") | F20: =SUM(B19:E19) | G20: =IF(F20=0,0,F19/F20)
A21: 합계 | B21: =SUM(B14:B19) | C21: =SUM(C14:C19) | D21: =SUM(D14:D19) | E21: =SUM(E14:E19) | F21: =SUM(F14:F19)
A23: 맞음+대체로 맞음 비율 | B23: =IF(F20=0,0,(F14+F15)/F20)

Sheet 안내
A1: 청해 판정표 보는 법
A3: 무엇 | B3: 내 말(사용자가 고친 자막 669줄)마다, 그 순간과 바로 앞의 애니 대사를 짝지어 두고, 대사를 옮기거나 따라 한 줄에 판정을 붙였다. 판정은 Claude가 했다.
A4: 유형 | B4: 따라함 = 일본어를 그대로 따라 말함 / 옮김 = 한국어로 뜻을 말함 / 추측 = 모르는 말의 뜻을 짐작함(~라는 말인가?) / 못알아들음 = 모르겠다고 말함 / 읽기 = 화면 글자를 읽음 / 기타 = AI 설명을 읽는 등 / 반응·혼잣말, 소리·감탄 = 판정 안 함(회색)
A5: 판정 | B5: 맞음(초록) / 대체로 맞음(연초록, 뜻은 맞고 말이 조금 다름) / 조금 맞음(노랑, 일부만 맞음) / 틀림(주황) / 못 알아들음(파랑, 모르겠다고 말함) / 확인 불가(회색, 짝지을 대사를 못 찾음)
A6: 대상 애니 대사 | B6: 판정한 기준 대사. 공식 일본어 자막(SDH)에서 가져왔다. [추정]은 녹화 시각을 앞뒤 대사로 짐작한 줄.
A7: 그 순간 애니 대사(참고) | B7: 내 말 직전 30초 안의 애니 대사 최대 3줄(회색).
A8: 채울 칸 | B8: 노란 칸만. 사용자 확인: 판정이 맞으면 "맞게 봄", 아니면 "판정 틀림"을 고르고 고친 판정을 고른다. 메모는 자유. 전부 볼 필요 없이 판정이 이상한 줄만 채워도 된다.
A9: 예시 | B9: 번호 232, 27:13 "아침에는" → 판정 "틀림"(아침에만 손님이 온다를 반대로 옮김). 그렇게 들은 게 아니면 "판정 틀림", 고친 판정 "대체로 맞음", 메모에 이유.
A10: 요약 시트 | B10: 유형별 줄 수와 판정 비율. 판정 시트를 고치면 다시 계산된다(판정 칸 F를 고칠 때).
